Workbook

Sheet lane1
A1: 任务单名称 | B1: 样本名称 | C1: 文库类型 | D1: 下单pooling数据量 | E1: i5Index序列 | F1: i7Index序列 | G1: 文库号 | H1: 浓度 | I1: 片段大小 | J1: 检测方法
A2: KC190225-001-DASH项目-DNA小片段测序分析技术服务-1期5例-DNA小片段文库-建库测序分析 | B2: 100%-WT | C2: DNA小片段 | D2: 0.01 | F2: GATGAATC | G2: HFDNA190226A0155-95 | H2: 61.5712 | I2: 506 | J2: QSEP 100
A3: KC190225-001-DASH项目-DNA小片段测序分析技术服务-1期5例-DNA小片段文库-建库测序分析 | B3: 10%-MT | C3: DNA小片段 | D3: 0.01 | F3: GCCAAGAC | G3: HFDNA190226A0156-96 | H3: 58.7799 | I3: 511 | J3: QSEP 100
A4: KC190225-001-DASH项目-DNA小片段测序分析技术服务-1期5例-DNA小片段文库-建库测序分析 | B4: 1%-MT | C4: DNA小片段 | D4: 0.01 | F4: AACGTGAT | G4: HFDNA190226A0157-1 | H4: 57.1268 | I4: 515 | J4: QSEP 100
A5: KC190225-001-DASH项目-DNA小片段测序分析技术服务-1期5例-DNA小片段文库-建库测序分析 | B5: 0.1%-MT | C5: DNA小片段 | D5: 0.01 | F5: AAACATCG | G5: HFDNA190226A0158-2 | H5: 60.8937 | I5: 514 | J5: QSEP 100
A6: KC190225-001-DASH项目-DNA小片段测序分析技术服务-1期5例-DNA小片段文库-建库测序分析 | B6: 100%-MT | C6: DNA小片段 | D6: 0.01 | F6: ATGCCTAA | G6: HFDNA190226A0159-3 | H6: 52.9534 | I6: 513 | J6: QSEP 100
A7: KC190312-003 KC190228-003 MAKF190110011-复旦大学51个样本的16S区域扩增子测序分析技术服务（委托）合同-1期51例-16sV3-V4-测序分析任务单 | B7: FA13-1 | C7: 16sV3-V4 | D7: 0.065 | E7: AGGTGCCG | F7: GCCGCATG | G7: HFMET190305A0476-87-124 | H7: =VLOOKUP(G7,[1]Meta文库质检结果汇总表!$E$2884:$R$3538,14,0) -> 14.0368 | I7: =VLOOKUP(G7,[1]Meta文库质检结果汇总表!$E$2355:$Q$3538,13,0) -> 614 | J7: =VLOOKUP(G7,[1]Meta文库质检结果汇总表!$E$1936:$O$3538,11,0) -> QSEP 100
A8: KC190312-003 KC190228-003 MAKF190110011-复旦大学51个样本的16S区域扩增子测序分析技术服务（委托）合同-1期51例-16sV3-V4-测序分析任务单 | B8: FA14-1 | C8: 16sV3-V4 | D8: 0.065 | E8: CTACGCAC | F8: GCCGCATG | G8: HFMET190305A0477-88-124 | H8: =VLOOKUP(G8,[1]Meta文库质检结果汇总表!$E$2884:$R$3538,14,0) -> 13.2308 | I8: =VLOOKUP(G8,[1]Meta文库质检结果汇总表!$E$2355:$Q$3538,13,0) -> 622 | J8: =VLOOKUP(G8,[1]Meta文库质检结果汇总表!$E$1936:$O$3538,11,0) -> QSEP 100
A9: KC190312-003 KC190228-003 MAKF190110011-复旦大学51个样本的16S区域扩增子测序分析技术服务（委托）合同-1期51例-16sV3-V4-测序分析任务单 | B9: FA15-1 | C9: 16sV3-V4 | D9: 0.065 | E9: GCGAAGTA | F9: GCCGCATG | G9: HFMET190305A0478-89-124 | H9: =VLOOKUP(G9,[1]Meta文库质检结果汇总表!$E$2884:$R$3538,14,0) -> 16.5044 | I9: =VLOOKUP(G9,[1]Meta文库质检结果汇总表!$E$2355:$Q$3538,13,0) -> 619 | J9: =VLOOKUP(G9,[1]Meta文库质检结果汇总表!$E$1936:$O$3538,11,0) -> QSEP 100
A10: KC190312-003 KC190228-003 MAKF190110011-复旦大学51个样本的16S区域扩增子测序分析技术服务（委托）合同-1期51例-16sV3-V4-测序分析任务单 | B10: FA16-1 | C10: 16sV3-V4 | D10: 0.065 | E10: TACTATGA | F10: GCCGCATG | G10: HFMET190305A0479-90-124 | H10: =VLOOKUP(G10,[1]Meta文库质检结果汇总表!$E$2884:$R$3538,14,0) -> 9.3868 | I10: =VLOOKUP(G10,[1]Meta文库质检结果汇总表!$E$2355:$Q$3538,13,0) -> 636 | J10: =VLOOKUP(G10,[1]Meta文库质检结果汇总表!$E$1936:$O$3538,11,0) -> QSEP 100
A11: KC190312-003 KC190228-003 MAKF190110011-复旦大学51个样本的16S区域扩增子测序分析技术服务（委托）合同-1期51例-16sV3-V4-测序分析任务单 | B11: FA17-1 | C11: 16sV3-V4 | D11: 0.065 | E11: AGGTTAAC | F11: GCCGCATG | G11: HFMET190305A0480-91-124 | H11: =VLOOKUP(G11,[1]Meta文库质检结果汇总表!$E$2884:$R$3538,14,0) -> 18.9596 | I11: =VLOOKUP(G11,[1]Meta文库质检结果汇总表!$E$2355:$Q$3538,13,0) -> 600 | J11: =VLOOKUP(G11,[1]Meta文库质检结果汇总表!$E$1936:$O$3538,11,0) -> QSEP 100
A12: KC190312-003 KC190228-003 MAKF190110011-复旦大学51个样本的16S区域扩增子测序分析技术服务（委托）合同-1期51例-16sV3-V4-测序分析任务单 | B12: FA18-1 | C12: 16sV3-V4 | D12: 0.065 | E12: CTACCATA | F12: GCCGCATG | G12: HFMET190305A0481-92-124 | H12: =VLOOKUP(G12,[1]Meta文库质检结果汇总表!$E$2884:$R$3538,14,0) -> 18.104 | I12: =VLOOKUP(G12,[1]Meta文库质检结果汇总表!$E$2355:$Q$3538,13,0) -> 611 | J12: =VLOOKUP(G12,[1]Meta文库质检结果汇总表!$E$1936:$O$3538,11,0) -> QSEP 100
A13: KC190312-003 KC190228-003 MAKF190110011-复旦大学51个样本的16S区域扩增子测序分析技术服务（委托）合同-1期51例-16sV3-V4-测序分析任务单 | B13: PM31-1 | C13: 16sV3-V4 | D13: 0.065 | E13: GCGACTCC | F13: GCCGCATG | G13: HFMET190305A0482-93-124 | H13: =VLOOKUP(G13,[1]Meta文库质检结果汇总表!$E$2884:$R$3538,14,0) -> 27.838 | I13: =VLOOKUP(G13,[1]Meta文库质检结果汇总表!$E$2355:$Q$3538,13,0) -> 606 | J13: =VLOOKUP(G13,[1]Meta文库质检结果汇总表!$E$1936:$O$3538,11,0) -> QSEP 100
A14: KC190312-003 KC190228-003 MAKF190110011-复旦大学51个样本的16S区域扩增子测序分析技术服务（委托）合同-1期51例-16sV3-V4-测序分析任务单 | B14: PM32-1 | C14: 16sV3-V4 | D14: 0.065 | E14: TAAGGCGC | F14: GCCGCATG | G14: HFMET190305A0483-94-124 | H14: =VLOOKUP(G14,[1]Meta文库质检结果汇总表!$E$2884:$R$3538,14,0) -> 23.498 | I14: =VLOOKUP(G14,[1]Meta文库质检结果汇总表!$E$2355:$Q$3538,13,0) -> 629 | J14: =VLOOKUP(G14,[1]Meta文库质检结果汇总表!$E$1936:$O$3538,11,0) -> QSEP 100
A15: KC190312-003 KC190228-003 MAKF190110011-复旦大学51个样本的16S区域扩增子测序分析技术服务（委托）合同-1期51例-16sV3-V4-测序分析任务单 | B15: PM33-1 | C15: 16sV3-V4 | D15: 0.065 | E15: AGGTGCCG | F15: CACGGCGA | G15: HFMET190305A0484-87-125 | H15: =VLOOKUP(G15,[1]Meta文库质检结果汇总表!$E$2884:$R$3538,14,0) -> 20.6708 | I15: =VLOOKUP(G15,[1]Meta文库质检结果汇总表!$E$2355:$Q$3538,13,0) -> 578 | J15: =VLOOKUP(G15,[1]Meta文库质检结果汇总表!$E$1936:$O$3538,11,0) -> QSEP 100
A16: KC190312-003 KC190228-003 MAKF190110011-复旦大学51个样本的16S区域扩增子测序分析技术服务（委托）合同-1期51例-16sV3-V4-测序分析任务单 | B16: PM34-1 | C16: 16sV3-V4 | D16: 0.065 | E16: CTACGCAC | F16: CACGGCGA | G16: HFMET190305A0485-88-125 | H16: =VLOOKUP(G16,[1]Meta文库质检结果汇总表!$E$2884:$R$3538,14,0) -> 17.1368 | I16: =VLOOKUP(G16,[1]Meta文库质检结果汇总表!$E$2355:$Q$3538,13,0) -> 616 | J16: =VLOOKUP(G16,[1]Meta文库质检结果汇总表!$E$1936:$O$3538,11,0) -> QSEP 100
A17: KC190312-003 KC190228-003 MAKF190110011-复旦大学51个样本的16S区域扩增子测序分析技术服务（委托）合同-1期51例-16sV3-V4-测序分析任务单 | B17: PM35-1 | C17: 16sV3-V4 | D17: 0.065 | E17: GCGAAGTA | F17: CACGGCGA | G17: HFMET190305A0486-89-125 | H17: =VLOOKUP(G17,[1]Meta文库质检结果汇总表!$E$2884:$R$3538,14,0) -> 14.3964 | I17: =VLOOKUP(G17,[1]Meta文库质检结果汇总表!$E$2355:$Q$3538,13,0) -> 594 | J17: =VLOOKUP(G17,[1]Meta文库质检结果汇总表!$E$1936:$O$3538,11,0) -> QSEP 100
A18: KC190312-003 KC190228-003 MAKF190110011-复旦大学51个样本的16S区域扩增子测序分析技术服务（委托）合同-1期51例-16sV3-V4-测序分析任务单 | B18: PM36-1 | C18: 16sV3-V4 | D18: 0.065 | E18: TACTATGA | F18: CACGGCGA | G18: HFMET190305A0487-90-125 | H18: =VLOOKUP(G18,[1]Meta文库质检结果汇总表!$E$2884:$R$3538,14,0) -> 14.074 | I18: =VLOOKUP(G18,[1]Meta文库质检结果汇总表!$E$2355:$Q$3538,13,0) -> 594 | J18: =VLOOKUP(G18,[1]Meta文库质检结果汇总表!$E$1936:$O$3538,11,0) -> QSEP 100
... A67: KC190312-001 MAKF190124012-安徽农业大学3个环境微生物DNA样本的16S ITS区域扩增子测序分析技术服务（委托）合同-1期6例-16sV3-V4&ITS1-测序分析任务单 | B67: 11-3 | C67: ITS1 | D67: 0.05 | E67: GAGCTGAC | F67: GTCCTACG | G67: HFMET190301A0465-59-68 | H67: =VLOOKUP(G67,[1]Meta文库质检结果汇总表!$E$2884:$R$3538,14,0) -> 24.7806 | I67: =VLOOKUP(G67,[1]Meta文库质检结果汇总表!$E$2355:$Q$3538,13,0) -> 338 | J67: =VLOOKUP(G67,[1]Meta文库质检结果汇总表!$E$1936:$O$3538,11,0) -> QSEP 100
A68: KC190313-002 MAKF181210014-孙建军12个人粪便样本的16S区域扩增子测序分析-3期7例-16sV3-V4-测序分析 | B68: 10 | C68: 16S V3-V4 | D68: 0.05 | E68: TTGGCGCC | F68: GCTTACGA | G68: HFMET190123A0156-109-114 | H68: =VLOOKUP(G68,[1]Meta文库质检结果汇总表!$E$3104:$AA$3110,23,0) -> 33.6582 | I68: =VLOOKUP(G68,[1]Meta文库质检结果汇总表!$E$3104:$Z$3110,22,0) -> 622 | J68: =VLOOKUP(G68,[1]Meta文库质检结果汇总表!$E$1936:$O$3538,11,0) -> FA SS 1-6K
A69: KC190313-002 MAKF181210014-孙建军12个人粪便样本的16S区域扩增子测序分析-3期7例-16sV3-V4-测序分析 | B69: 24 | C69: 16S V3-V4 | D69: 0.05 | E69: CATCATAA | F69: GCTTACGA | G69: HFMET190123A0157-110-114 | H69: =VLOOKUP(G69,[1]Meta文库质检结果汇总表!$E$3104:$AA$3110,23,0) -> 46.6391 | I69: =VLOOKUP(G69,[1]Meta文库质检结果汇总表!$E$3104:$Z$3110,22,0) -> 608 | J69: =VLOOKUP(G69,[1]Meta文库质检结果汇总表!$E$1936:$O$3538,11,0) -> FA SS 1-6K
A70: KC190313-002 MAKF181210014-孙建军12个人粪便样本的16S区域扩增子测序分析-3期7例-16sV3-V4-测序分析 | B70: 25 | C70: 16S V3-V4 | D70: 0.05 | E70: AAGGATGC | F70: TCGGCGAT | G70: HFMET190123A0158-95-119 | H70: =VLOOKUP(G70,[1]Meta文库质检结果汇总表!$E$3104:$AA$3110,23,0) -> 38.5633 | I70: =VLOOKUP(G70,[1]Meta文库质检结果汇总表!$E$3104:$Z$3110,22,0) -> 597 | J70: =VLOOKUP(G70,[1]Meta文库质检结果汇总表!$E$1936:$O$3538,11,0) -> FA SS 1-6K
A71: KC190313-002 MAKF181210014-孙建军12个人粪便样本的16S区域扩增子测序分析-3期7例-16sV3-V4-测序分析 | B71: 29 | C71: 16S V3-V4 | D71: 0.05 | E71: GGCCGGTT | F71: TCGGCGAT | G71: HFMET190123A0159-96-119 | H71: =VLOOKUP(G71,[1]Meta文库质检结果汇总表!$E$3104:$AA$3110,23,0) -> 39.9454 | I71: =VLOOKUP(G71,[1]Meta文库质检结果汇总表!$E$3104:$Z$3110,22,0) -> 591 | J71: =VLOOKUP(G71,[1]Meta文库质检结果汇总表!$E$1936:$O$3538,11,0) -> FA SS 1-6K
A72: KC190313-002 MAKF181210014-孙建军12个人粪便样本的16S区域扩增子测序分析-3期7例-16sV3-V4-测序分析 | B72: 26-2 | C72: 16S V3-V4 | D72: 0.05 | E72: CCGGCTAA | F72: TCGGCGAT | G72: HFMET190123A0160-97-119 | H72: =VLOOKUP(G72,[1]Meta文库质检结果汇总表!$E$3104:$AA$3110,23,0) -> 29.1054 | I72: =VLOOKUP(G72,[1]Meta文库质检结果汇总表!$E$3104:$Z$3110,22,0) -> 631 | J72: =VLOOKUP(G72,[1]Meta文库质检结果汇总表!$E$1936:$O$3538,11,0) -> FA SS 1-6K
A73: KC190313-002 MAKF181210014-孙建军12个人粪便样本的16S区域扩增子测序分析-3期7例-16sV3-V4-测序分析 | B73: 27-2 | C73: 16S V3-V4 | D73: 0.05 | E73: TTGCTACG | F73: TCGGCGAT | G73: HFMET190123A0161-98-119 | H73: =VLOOKUP(G73,[1]Meta文库质检结果汇总表!$E$3104:$AA$3110,23,0) -> 26.3954 | I73: =VLOOKUP(G73,[1]Meta文库质检结果汇总表!$E$3104:$Z$3110,22,0) -> 628 | J73: =VLOOKUP(G73,[1]Meta文库质检结果汇总表!$E$1936:$O$3538,11,0) -> FA SS 1-6K
A74: KC190313-002 MAKF181210014-孙建军12个人粪便样本的16S区域扩增子测序分析-3期7例-16sV3-V4-测序分析 | B74: 28-2 | C74: 16S V3-V4 | D74: 0.05 | E74: ACACGCGG | F74: TCGGCGAT | G74: HFMET190123A0162-99-119 | H74: =VLOOKUP(G74,[1]Meta文库质检结果汇总表!$E$3104:$AA$3110,23,0) -> 27.7233 | I74: =VLOOKUP(G74,[1]Meta文库质检结果汇总表!$E$3104:$Z$3110,22,0) -> 640 | J74: =VLOOKUP(G74,[1]Meta文库质检结果汇总表!$E$1936:$O$3538,11,0) -> FA SS 1-6K
A75: KC190313-004 MAKF181112011-省农科院500个样本的16S区域扩增子测序分析技术服务（委托）合同-4期99例-16sV3-V4-测序分析任务单 | B75: LX-CeC1 | C75: 16sV3-V4 | D75: 0.065 | E75: CATTGCTT | F75: TCGGCGAT | G75: HFMET190301A0358-1-119 | H75: =VLOOKUP(G75,[1]Meta文库质检结果汇总表!$E$2884:$R$3538,14,0) -> 14.4963 | I75: =VLOOKUP(G75,[1]Meta文库质检结果汇总表!$E$2355:$Q$3538,13,0) -> 639 | J75: =VLOOKUP(G75,[1]Meta文库质检结果汇总表!$E$1936:$O$3538,11,0) -> QSEP 100
A76: KC190313-004 MAKF181112011-省农科院500个样本的16S区域扩增子测序分析技术服务（委托）合同-4期99例-16sV3-V4-测序分析任务单 | B76: LX-CeC2 | C76: 16sV3-V4 | D76: 0.065 | E76: ATGAACCT | F76: TCGGCGAT | G76: HFMET190301A0359-16-119 | H76: =VLOOKUP(G76,[1]Meta文库质检结果汇总表!$E$2884:$R$3538,14,0) -> 16.1217 | I76: =VLOOKUP(G76,[1]Meta文库质检结果汇总表!$E$2355:$Q$3538,13,0) -> 641 | J76: =VLOOKUP(G76,[1]Meta文库质检结果汇总表!$E$1936:$O$3538,11,0) -> QSEP 100
A77: KC190313-004 MAKF181112011-省农科院500个样本的16S区域扩增子测序分析技术服务（委托）合同-4期99例-16sV3-V4-测序分析任务单 | B77: LX-CeC3 | C77: 16sV3-V4 | D77: 0.065 | E77: ACCAGACT | F77: TCGGCGAT | G77: HFMET190301A0360-17-119 | H77: =VLOOKUP(G77,[1]Meta文库质检结果汇总表!$E$2884:$R$3538,14,0) -> 21.0924 | I77: =VLOOKUP(G77,[1]Meta文库质检结果汇总表!$E$2355:$Q$3538,13,0) -> 636 | J77: =VLOOKUP(G77,[1]Meta文库质检结果汇总表!$E$1936:$O$3538,11,0) -> QSEP 100
A78: KC190313-004 MAKF181112011-省农科院500个样本的16S区域扩增子测序分析技术服务（委托）合同-4期99例-16sV3-V4-测序分析任务单 | B78: LX-CeC4 | C78: 16sV3-V4 | D78: 0.065 | E78: TCTTATAT | F78: TCGGCGAT | G78: HFMET190301A0361-21-119 | H78: =VLOOKUP(G78,[1]Meta文库质检结果汇总表!$E$2884:$R$3538,14,0) -> 18.7677 | I78: =VLOOKUP(G78,[1]Meta文库质检结果汇总表!$E$2355:$Q$3538,13,0) -> 674 | J78: =VLOOKUP(G78,[1]Meta文库质检结果汇总表!$E$1936:$O$3538,11,0) -> QSEP 100
A79: KC190313-004 MAKF181112011-省农科院500个样本的16S区域扩增子测序分析技术服务（委托）合同-4期99例-16sV3-V4-测序分析任务单 | B79: LX-CeC5 | C79: 16sV3-V4 | D79: 0.065 | E79: GTTACTTG | F79: TCGGCGAT | G79: HFMET190301A0362-27-119 | H79: =VLOOKUP(G79,[1]Meta文库质检结果汇总表!$E$2884:$R$3538,14,0) -> 15.2901 | I79: =VLOOKUP(G79,[1]Meta文库质检结果汇总表!$E$2355:$Q$3538,13,0) -> 665 | J79: =VLOOKUP(G79,[1]Meta文库质检结果汇总表!$E$1936:$O$3538,11,0) -> QSEP 100
A80: KC190313-004 MAKF181112011-省农科院500个样本的16S区域扩增子测序分析技术服务（委托）合同-4期99例-16sV3-V4-测序分析任务单 | B80: LX-CeC6 | C80: 16sV3-V4 | D80: 0.065 | E80: TGACAGAC | F80: TCGGCGAT | G80: HFMET190301A0363-84-119 | H80: =VLOOKUP(G80,[1]Meta文库质检结果汇总表!$E$2884:$R$3538,14,0) -> 14.8743 | I80: =VLOOKUP(G80,[1]Meta文库质检结果汇总表!$E$2355:$Q$3538,13,0) -> 653 | J80: =VLOOKUP(G80,[1]Meta文库质检结果汇总表!$E$1936:$O$3538,11,0) -> QSEP 100
A81: KC190313-004 MAKF181112011-省农科院500个样本的16S区域扩增子测序分析技术服务（委托）合同-4期99例-16sV3-V4-测序分析任务单 | B81: LX-CeC7 | C81: 16sV3-V4 | D81: 0.065 | E81: CCGTCACG | F81: TCGGCGAT | G81: HFMET190301A0364-85-119 | H81: =VLOOKUP(G81,[1]Meta文库质检结果汇总表!$E$2884:$R$3538,14,0) -> 17.5959 | I81: =VLOOKUP(G81,[1]Meta文库质检结果汇总表!$E$2355:$Q$3538,13,0) -> 654 | J81: =VLOOKUP(G81,[1]Meta文库质检结果汇总表!$E$1936:$O$3538,11,0) -> QSEP 100
A82: KC190313-004 MAKF181112011-省农科院500个样本的16S区域扩增子测序分析技术服务（委托）合同-4期99例-16sV3-V4-测序分析任务单 | B82: LX-CeC8 | C82: 16sV3-V4 | D82: 0.065 | E82: GTTGCAAC | F82: TCGGCGAT | G82: HFMET190301A0365-86-119 | H82: =VLOOKUP(G82,[1]Meta文库质检结果汇总表!$E$2884:$R$3538,14,0) -> 16.8777 | I82: =VLOOKUP(G82,[1]Meta文库质检结果汇总表!$E$2355:$Q$3538,13,0) -> 656 | J82: =VLOOKUP(G82,[1]Meta文库质检结果汇总表!$E$1936:$O$3538,11,0) -> QSEP 100
A83: KC190313-004 MAKF181112011-省农科院500个样本的16S区域扩增子测序分析技术服务（委托）合同-4期99例-16sV3-V4-测序分析任务单 | B83: LX-CeC9 | C83: 16sV3-V4 | D83: 0.065 | E83: CATTGCTT | F83: GAATTCCA | G83: HFMET190301A0366-1-120 | H83: =VLOOKUP(G83,[1]Meta文库质检结果汇总表!$E$2884:$R$3538,14,0) -> 22.8879 | I83: =VLOOKUP(G83,[1]Meta文库质检结果汇总表!$E$2355:$Q$3538,13,0) -> 631 | J83: =VLOOKUP(G83,[1]Meta文库质检结果汇总表!$E$1936:$O$3538,11,0) -> QSEP 100
A84: KC190313-004 MAKF181112011-省农科院500个样本的16S区域扩增子测序分析技术服务（委托）合同-4期99例-16sV3-V4-测序分析任务单 | B84: LX-CeC10 | C84: 16sV3-V4 | D84: 0.065 | E84: ATGAACCT | F84: GAATTCCA | G84: HFMET190301A0367-16-120 | H84: =VLOOKUP(G84,[1]Meta文库质检结果汇总表!$E$2884:$R$3538,14,0) -> 13.6458 | I84: =VLOOKUP(G84,[1]Meta文库质检结果汇总表!$E$2355:$Q$3538,13,0) -> 651 | J84: =VLOOKUP(G84,[1]Meta文库质检结果汇总表!$E$1936:$O$3538,11,0) -> QSEP 100
A85: KC190313-004 MAKF181112011-省农科院500个样本的16S区域扩增子测序分析技术服务（委托）合同-4期99例-16sV3-V4-测序分析任务单 | B85: LX-CeC11 | C85: 16sV3-V4 | D85: 0.065 | E85: ACCAGACT | F85: GAATTCCA | G85: HFMET190301A0368-17-120 | H85: =VLOOKUP(G85,[1]Meta文库质检结果汇总表!$E$2884:$R$3538,14,0) -> 21.2058 | I85: =VLOOKUP(G85,[1]Meta文库质检结果汇总表!$E$2355:$Q$3538,13,0) -> 634 | J85: =VLOOKUP(G85,[1]Meta文库质检结果汇总表!$E$1936:$O$3538,11,0) -> QSEP 100
A86: KC190313-004 MAKF181112011-省农科院500个样本的16S区域扩增子测序分析技术服务（委托）合同-4期99例-16sV3-V4-测序分析任务单 | B86: LX-CeC12 | C86: 16sV3-V4 | D86: 0.065 | E86: TCTTATAT | F86: GAATTCCA | G86: HFMET190301A0369-21-120 | H86: =VLOOKUP(G86,[1]Meta文库质检结果汇总表!$E$2884:$R$3538,14,0) -> 21.735 | I86: =VLOOKUP(G86,[1]Meta文库质检结果汇总表!$E$2355:$Q$3538,13,0) -> 661 | J86: =VLOOKUP(G86,[1]Meta文库质检结果汇总表!$E$1936:$O$3538,11,0) -> QSEP 100
... A173: KC190313-004 MAKF181112011-省农科院500个样本的16S区域扩增子测序分析技术服务（委托）合同-4期99例-16sV3-V4-测序分析任务单 | B173: HEBCeC-31 | C173: 16sV3-V4 | D173: 0.065 | E173: GCGAAGTA | F173: TCCTCACT | G173: HFMET190301A0456-89-123 | H173: =VLOOKUP(G173,[1]Meta文库质检结果汇总表!$E$2884:$R$3538,14,0) -> 12.2283 | I173: =VLOOKUP(G173,[1]Meta文库质检结果汇总表!$E$2355:$Q$3538,13,0) -> 633 | J173: =VLOOKUP(G173,[1]Meta文库质检结果汇总表!$E$1936:$O$3538,11,0) -> QSEP 100
A174: KC190313-004 MAKF181112011-省农科院500个样本的16S区域扩增子测序分析技术服务（委托）合同-4期99例-16sV3-V4-测序分析任务单 | B174: LX-HN(混合) | C174: 16sV3-V4 | D174: 0.065 | E174: ACCAGACT | F174: GCGAGGCC | G174: HFMET181123A2581-17-133 | H174: 25.4051 | I174: =VLOOKUP(G174,[1]Meta文库质检结果汇总表!$E$2355:$Q$3538,13,0) -> 608 | J174: =VLOOKUP(G174,[1]Meta文库质检结果汇总表!$E$1936:$O$3538,11,0) -> 0
...

Sheet Sheet1
A1: 任务单名称 | B1: 样本名称 | C1: 文库类型 | D1: 下单pooling数据量 | E1: i5Index序列 | F1: i7Index序列 | G1: 文库号 | H1: 浓度 | I1: 片段大小 | J1: 检测方法
A2: KC190308-001 MAKF190117012-成医4个PCR产物样本的建库测序技术服务（委托）合同-PCR产物-第1期4例-建库测序 | B2: ECC | C2: PCR free文库 | D2: 0.06 | F2: AGTACAAG | G2: FKDN190253888-1A
A3: KC190308-001 MAKF190117012-成医4个PCR产物样本的建库测序技术服务（委托）合同-PCR产物-第1期4例-建库测序 | B3: EGC | C3: PCR free文库 | D3: 0.06 | F3: CAGCGTTA | G3: FKDN190253889-1A
A4: KC190308-001 MAKF190117012-成医4个PCR产物样本的建库测序技术服务（委托）合同-PCR产物-第1期4例-建库测序 | B4: ECT | C4: PCR free文库 | D4: 0.06 | F4: GAGCTGAA | G4: FKDN190253890-1A
A5: KC190308-001 MAKF190117012-成医4个PCR产物样本的建库测序技术服务（委托）合同-PCR产物-第1期4例-建库测序 | B5: ETC | C5: PCR free文库 | D5: 0.06 | F5: TGGTGGTA | G5: FKDN190253891-1A
