Workbook

Sheet 样本明细表
A1: 任务单名称 | B1: 样本名称 | C1: 核酸编号 | D1: 文库类型 | E1: pooling数据量 | F1: Index(诺唯赞） | G1: 储位 | H1: 文库号 | I1: 浓度 | J1: 大小
A2: KC190123-001 MAKF190116012-省农科院650个样本的16S区域扩增子测序分析技术服务（委托）合同-1期121例-16sV3-V4-测序分析任务单 | B2: LX-HN(混合) | C2: HF181119100 | D2: 16sV3-V4 | E2: 0.07 | F2: 17-133 | G2: Meta 53，B01 | H2: HFMET181123A2581-17-133 | I2: =VLOOKUP(H2,[1]Meta文库质检结果汇总表!$E:$AH,14,0) -> 25.4051 | J2: 608
A3: KC190123-001 MAKF190116012-省农科院650个样本的16S区域扩增子测序分析技术服务（委托）合同-1期121例-16sV3-V4-测序分析任务单 | B3: MD1d CeC 1 | C3: HF190117001 | D3: 16sV3-V4 | E3: 0.07 | F3: 1-111 | G3: MetB 61，B07 | H3: HFMET190128A0216-1-111 | I3: =VLOOKUP(H3,[1]Meta文库质检结果汇总表!$E:$AH,14,0) -> 36.4018 | J3: =VLOOKUP(H3,[1]Meta文库质检结果汇总表!$E$3104:$Q$3355,13,0) -> 613
A4: KC190123-001 MAKF190116012-省农科院650个样本的16S区域扩增子测序分析技术服务（委托）合同-1期121例-16sV3-V4-测序分析任务单 | B4: MD1d CeC 2 | C4: HF190117002 | D4: 16sV3-V4 | E4: 0.07 | F4: 1-112 | G4: MetB 61，B08 | H4: HFMET190128A0217-1-112 | I4: =VLOOKUP(H4,[1]Meta文库质检结果汇总表!$E:$AH,14,0) -> 29.7852 | J4: =VLOOKUP(H4,[1]Meta文库质检结果汇总表!$E$3104:$Q$3355,13,0) -> 608
A5: KC190123-001 MAKF190116012-省农科院650个样本的16S区域扩增子测序分析技术服务（委托）合同-1期121例-16sV3-V4-测序分析任务单 | B5: MD1d CeC 3 | C5: HF190117003 | D5: 16sV3-V4 | E5: 0.07 | F5: 1-113 | G5: MetB 61，B09 | H5: HFMET190128A0218-1-113 | I5: =VLOOKUP(H5,[1]Meta文库质检结果汇总表!$E:$AH,14,0) -> 27.2619 | J5: =VLOOKUP(H5,[1]Meta文库质检结果汇总表!$E$3104:$Q$3355,13,0) -> 608
A6: KC190123-001 MAKF190116012-省农科院650个样本的16S区域扩增子测序分析技术服务（委托）合同-1期121例-16sV3-V4-测序分析任务单 | B6: MD1d CeC 4 | C6: HF190117004 | D6: 16sV3-V4 | E6: 0.07 | F6: 1-114 | G6: MetB 61，B10 | H6: HFMET190128A0219-1-114 | I6: =VLOOKUP(H6,[1]Meta文库质检结果汇总表!$E:$AH,14,0) -> 33.4067 | J6: =VLOOKUP(H6,[1]Meta文库质检结果汇总表!$E$3104:$Q$3355,13,0) -> 623
A7: KC190123-001 MAKF190116012-省农科院650个样本的16S区域扩增子测序分析技术服务（委托）合同-1期121例-16sV3-V4-测序分析任务单 | B7: MD1d CeC 5 | C7: HF190117005 | D7: 16sV3-V4 | E7: 0.07 | F7: 1-115 | G7: MetB 61，B11 | H7: HFMET190128A0220-1-115 | I7: =VLOOKUP(H7,[1]Meta文库质检结果汇总表!$E:$AH,14,0) -> 16.5216 | J7: =VLOOKUP(H7,[1]Meta文库质检结果汇总表!$E$3104:$Q$3355,13,0) -> 609
A8: KC190123-001 MAKF190116012-省农科院650个样本的16S区域扩增子测序分析技术服务（委托）合同-1期121例-16sV3-V4-测序分析任务单 | B8: MD1d CeC 6 | C8: HF190117006 | D8: 16sV3-V4 | E8: 0.07 | F8: 16-111 | G8: MetB 61，B12 | H8: HFMET190128A0221-16-111 | I8: =VLOOKUP(H8,[1]Meta文库质检结果汇总表!$E:$AH,14,0) -> 71.1826 | J8: =VLOOKUP(H8,[1]Meta文库质检结果汇总表!$E$3104:$Q$3355,13,0) -> 613
A9: KC190123-001 MAKF190116012-省农科院650个样本的16S区域扩增子测序分析技术服务（委托）合同-1期121例-16sV3-V4-测序分析任务单 | B9: MD1d CeC 7 | C9: HF190117007 | D9: 16sV3-V4 | E9: 0.07 | F9: 16-112 | G9: Meta 61，C01 | H9: HFMET190128A0222-16-112 | I9: =VLOOKUP(H9,[1]Meta文库质检结果汇总表!$E:$AH,14,0) -> 35.8865 | J9: =VLOOKUP(H9,[1]Meta文库质检结果汇总表!$E$3104:$Q$3355,13,0) -> 610
A10: KC190123-001 MAKF190116012-省农科院650个样本的16S区域扩增子测序分析技术服务（委托）合同-1期121例-16sV3-V4-测序分析任务单 | B10: MD1d CeC 8 | C10: HF190117008 | D10: 16sV3-V4 | E10: 0.07 | F10: 16-113 | G10: Meta 61，C02 | H10: HFMET190128A0223-16-113 | I10: =VLOOKUP(H10,[1]Meta文库质检结果汇总表!$E:$AH,14,0) -> 58.0645 | J10: =VLOOKUP(H10,[1]Meta文库质检结果汇总表!$E$3104:$Q$3355,13,0) -> 627
A11: KC190123-001 MAKF190116012-省农科院650个样本的16S区域扩增子测序分析技术服务（委托）合同-1期121例-16sV3-V4-测序分析任务单 | B11: MD3d CeC 1 | C11: HF190117009 | D11: 16sV3-V4 | E11: 0.07 | F11: 16-114 | G11: Meta 61，C03 | H11: HFMET190128A0224-16-114 | I11: =VLOOKUP(H11,[1]Meta文库质检结果汇总表!$E:$AH,14,0) -> 52.9582 | J11: =VLOOKUP(H11,[1]Meta文库质检结果汇总表!$E$3104:$Q$3355,13,0) -> 632
A12: KC190123-001 MAKF190116012-省农科院650个样本的16S区域扩增子测序分析技术服务（委托）合同-1期121例-16sV3-V4-测序分析任务单 | B12: MD3d CeC 2 | C12: HF190117010 | D12: 16sV3-V4 | E12: 0.07 | F12: 16-115 | G12: Meta 61，C04 | H12: HFMET190128A0225-16-115 | I12: =VLOOKUP(H12,[1]Meta文库质检结果汇总表!$E:$AH,14,0) -> 54.1428 | J12: =VLOOKUP(H12,[1]Meta文库质检结果汇总表!$E$3104:$Q$3355,13,0) -> 626
A13: KC190123-001 MAKF190116012-省农科院650个样本的16S区域扩增子测序分析技术服务（委托）合同-1期121例-16sV3-V4-测序分析任务单 | B13: MD3d CeC 3 | C13: HF190117011 | D13: 16sV3-V4 | E13: 0.07 | F13: 17-111 | G13: Meta 61，C05 | H13: HFMET190128A0226-17-111 | I13: =VLOOKUP(H13,[1]Meta文库质检结果汇总表!$E:$AH,14,0) -> 84.5241 | J13: =VLOOKUP(H13,[1]Meta文库质检结果汇总表!$E$3104:$Q$3355,13,0) -> 620
A14: KC190123-001 MAKF190116012-省农科院650个样本的16S区域扩增子测序分析技术服务（委托）合同-1期121例-16sV3-V4-测序分析任务单 | B14: MD3d CeC 4 | C14: HF190117012 | D14: 16sV3-V4 | E14: 0.07 | F14: 17-112 | G14: Meta 61，C06 | H14: HFMET190128A0227-17-112 | I14: =VLOOKUP(H14,[1]Meta文库质检结果汇总表!$E:$AH,14,0) -> 79.7414 | J14: =VLOOKUP(H14,[1]Meta文库质检结果汇总表!$E$3104:$Q$3355,13,0) -> 624
... A124: KC190219-001 MAKF181116017-辽宁大学生命科学院50个杂色山雀粪便样本的16S区域扩增子测序分析-2期2例-16sV3-V4-测序分析 | B124: Z7 | C124: HFED181211007A | D124: 16sV3-V4 | E124: 0.06 | F124: 102-119 | G124: Meta 60，F01 | H124: HFMET190123A0165-102-119 | I124: =VLOOKUP(H124,[1]Meta文库质检结果汇总表!$E:$AH,14,0) -> 7.2173 | J124: =VLOOKUP(H124,[1]Meta文库质检结果汇总表!$E$3104:$Q$3355,13,0) -> 583
A125: KC190221-007 MAKF181229011-浙大93个样本的16S区域扩增子建库测序技术服务（委托）合同-2期26例-16sV4-V5-测序分析任务单 | B125: 529 | C125: HF190111001 | D125: 16sV4-V5 | E125: 0.06 | F125: 55-78 | G125: Meta 60，G01 | H125: HFMET190125A0174-55-78 | I125: =VLOOKUP(H125,[1]Meta文库质检结果汇总表!$E:$AH,14,0) -> 6.7121 | J125: =VLOOKUP(H125,[1]Meta文库质检结果汇总表!$E$3104:$Q$3355,13,0) -> 521
A126: KC190221-007 MAKF181229011-浙大93个样本的16S区域扩增子建库测序技术服务（委托）合同-2期26例-16sV4-V5-测序分析任务单 | B126: 533 | C126: HF190111002 | D126: 16sV4-V5 | E126: 0.06 | F126: 56-78 | G126: Meta 60，G02 | H126: HFMET190125A0175-56-78 | I126: =VLOOKUP(H126,[1]Meta文库质检结果汇总表!$E:$AH,14,0) -> 0.988 | J126: =VLOOKUP(H126,[1]Meta文库质检结果汇总表!$E$3104:$Q$3355,13,0) -> 527
A127: KC190221-007 MAKF181229011-浙大93个样本的16S区域扩增子建库测序技术服务（委托）合同-2期26例-16sV4-V5-测序分析任务单 | B127: 942 | C127: HF190111003 | D127: 16sV4-V5 | E127: 0.06 | F127: 57-78 | G127: Meta 60，G03 | H127: HFMET190125A0176-57-78 | I127: =VLOOKUP(H127,[1]Meta文库质检结果汇总表!$E:$AH,14,0) -> 1.8662 | J127: =VLOOKUP(H127,[1]Meta文库质检结果汇总表!$E$3104:$Q$3355,13,0) -> 520
A128: KC190221-007 MAKF181229011-浙大93个样本的16S区域扩增子建库测序技术服务（委托）合同-2期26例-16sV4-V5-测序分析任务单 | B128: 943 | C128: HF190111004 | D128: 16sV4-V5 | E128: 0.06 | F128: 58-78 | G128: Meta 62，F05 | H128: HFMET190129B0177-58-78 | I128: =VLOOKUP(H128,[1]Meta文库质检结果汇总表!$E:$AH,14,0) -> 1.3046 | J128: =VLOOKUP(H128,[1]Meta文库质检结果汇总表!$E$3104:$Q$3355,13,0) -> 529
A129: KC190221-007 MAKF181229011-浙大93个样本的16S区域扩增子建库测序技术服务（委托）合同-2期26例-16sV4-V5-测序分析任务单 | B129: 946 | C129: HF190111005 | D129: 16sV4-V5 | E129: 0.06 | F129: 51-79 | G129: Meta 60，G05 | H129: HFMET190125A0178-51-79 | I129: =VLOOKUP(H129,[1]Meta文库质检结果汇总表!$E:$AH,14,0) -> 7.4231 | J129: =VLOOKUP(H129,[1]Meta文库质检结果汇总表!$E$3104:$Q$3355,13,0) -> 527
A130: KC190221-007 MAKF181229011-浙大93个样本的16S区域扩增子建库测序技术服务（委托）合同-2期26例-16sV4-V5-测序分析任务单 | B130: 2976 | C130: HF190111006 | D130: 16sV4-V5 | E130: 0.06 | F130: 52-79 | G130: Meta 60，G06 | H130: HFMET190125A0179-52-79 | I130: =VLOOKUP(H130,[1]Meta文库质检结果汇总表!$E:$AH,14,0) -> 9.163 | J130: =VLOOKUP(H130,[1]Meta文库质检结果汇总表!$E$3104:$Q$3355,13,0) -> 542
A131: KC190221-007 MAKF181229011-浙大93个样本的16S区域扩增子建库测序技术服务（委托）合同-2期26例-16sV4-V5-测序分析任务单 | B131: 2977 | C131: HF190111007 | D131: 16sV4-V5 | E131: 0.06 | F131: 53-79 | G131: Meta 60，G07 | H131: HFMET190125A0180-53-79 | I131: =VLOOKUP(H131,[1]Meta文库质检结果汇总表!$E:$AH,14,0) -> 11.344 | J131: =VLOOKUP(H131,[1]Meta文库质检结果汇总表!$E$3104:$Q$3355,13,0) -> 547
A132: KC190221-007 MAKF181229011-浙大93个样本的16S区域扩增子建库测序技术服务（委托）合同-2期26例-16sV4-V5-测序分析任务单 | B132: 1409 | C132: HF190111008 | D132: 16sV4-V5 | E132: 0.06 | F132: 54-79 | G132: Meta 60，G08 | H132: HFMET190125A0181-54-79 | I132: =VLOOKUP(H132,[1]Meta文库质检结果汇总表!$E:$AH,14,0) -> 19.712 | J132: =VLOOKUP(H132,[1]Meta文库质检结果汇总表!$E$3104:$Q$3355,13,0) -> 549
A133: KC190221-007 MAKF181229011-浙大93个样本的16S区域扩增子建库测序技术服务（委托）合同-2期26例-16sV4-V5-测序分析任务单 | B133: 1636 | C133: HF190111009 | D133: 16sV4-V5 | E133: 0.06 | F133: 55-79 | G133: Meta 60，G09 | H133: HFMET190125A0182-55-79 | I133: =VLOOKUP(H133,[1]Meta文库质检结果汇总表!$E:$AH,14,0) -> 26.0946 | J133: =VLOOKUP(H133,[1]Meta文库质检结果汇总表!$E$3104:$Q$3355,13,0) -> 533
A134: KC190221-007 MAKF181229011-浙大93个样本的16S区域扩增子建库测序技术服务（委托）合同-2期26例-16sV4-V5-测序分析任务单 | B134: 1625 | C134: HF190111010 | D134: 16sV4-V5 | E134: 0.06 | F134: 56-79 | G134: Meta 60，G10 | H134: HFMET190125A0183-56-79 | I134: =VLOOKUP(H134,[1]Meta文库质检结果汇总表!$E:$AH,14,0) -> 2.9582 | J134: =VLOOKUP(H134,[1]Meta文库质检结果汇总表!$E$3104:$Q$3355,13,0) -> 538
A135: KC190221-007 MAKF181229011-浙大93个样本的16S区域扩增子建库测序技术服务（委托）合同-2期26例-16sV4-V5-测序分析任务单 | B135: 5746 | C135: HF190111011 | D135: 16sV4-V5 | E135: 0.06 | F135: 57-79 | G135: Meta 60，G11 | H135: HFMET190125A0184-57-79 | I135: =VLOOKUP(H135,[1]Meta文库质检结果汇总表!$E:$AH,14,0) -> 12.5782 | J135: =VLOOKUP(H135,[1]Meta文库质检结果汇总表!$E$3104:$Q$3355,13,0) -> 527
A136: KC190221-007 MAKF181229011-浙大93个样本的16S区域扩增子建库测序技术服务（委托）合同-2期26例-16sV4-V5-测序分析任务单 | B136: 2989 | C136: HF190111012 | D136: 16sV4-V5 | E136: 0.06 | F136: 58-79 | G136: Meta 60，G12 | H136: HFMET190125A0185-58-79 | I136: =VLOOKUP(H136,[1]Meta文库质检结果汇总表!$E:$AH,14,0) -> 23.6438 | J136: =VLOOKUP(H136,[1]Meta文库质检结果汇总表!$E$3104:$Q$3355,13,0) -> 535
A137: KC190221-007 MAKF181229011-浙大93个样本的16S区域扩增子建库测序技术服务（委托）合同-2期26例-16sV4-V5-测序分析任务单 | B137: 1638 | C137: HF190111013 | D137: 16sV4-V5 | E137: 0.06 | F137: 51-80 | G137: Meta 60，H01 | H137: HFMET190125A0186-51-80 | I137: =VLOOKUP(H137,[1]Meta文库质检结果汇总表!$E:$AH,14,0) -> 3.1896 | J137: =VLOOKUP(H137,[1]Meta文库质检结果汇总表!$E$3104:$Q$3355,13,0) -> 526
A138: KC190221-007 MAKF181229011-浙大93个样本的16S区域扩增子建库测序技术服务（委托）合同-2期26例-16sV4-V5-测序分析任务单 | B138: CK7 | C138: HF190111015 | D138: 16sV4-V5 | E138: 0.06 | F138: 53-80 | G138: Meta 62，F07 | H138: HFMET190129B0188-53-80 | I138: =VLOOKUP(H138,[1]Meta文库质检结果汇总表!$E:$AH,14,0) -> 1.2222 | J138: =VLOOKUP(H138,[1]Meta文库质检结果汇总表!$E$3104:$Q$3355,13,0) -> 552
A139: KC190221-007 MAKF181229011-浙大93个样本的16S区域扩增子建库测序技术服务（委托）合同-2期26例-16sV4-V5-测序分析任务单 | B139: B61 18 | C139: HF190111021 | D139: 16sV4-V5 | E139: 0.06 | F139: 51-81 | G139: Meta 60，H09 | H139: HFMET190125A0194-51-81 | I139: =VLOOKUP(H139,[1]Meta文库质检结果汇总表!$E:$AH,14,0) -> 5.9558 | J139: =VLOOKUP(H139,[1]Meta文库质检结果汇总表!$E$3104:$Q$3355,13,0) -> 528
A140: KC190221-007 MAKF181229011-浙大93个样本的16S区域扩增子建库测序技术服务（委托）合同-2期26例-16sV4-V5-测序分析任务单 | B140: B61 25 | C140: HF190111023 | D140: 16sV4-V5 | E140: 0.06 | F140: 53-81 | G140: Meta 60，H11 | H140: HFMET190125A0196-53-81 | I140: =VLOOKUP(H140,[1]Meta文库质检结果汇总表!$E:$AH,14,0) -> 22.1733 | J140: =VLOOKUP(H140,[1]Meta文库质检结果汇总表!$E$3104:$Q$3355,13,0) -> 541
A141: KC190221-007 MAKF181229011-浙大93个样本的16S区域扩增子建库测序技术服务（委托）合同-2期26例-16sV4-V5-测序分析任务单 | B141: B61 27 | C141: HF190111025 | D141: 16sV4-V5 | E141: 0.06 | F141: 55-81 | G141: Meta 61，A01 | H141: HFMET190125A0198-55-81 | I141: =VLOOKUP(H141,[1]Meta文库质检结果汇总表!$E:$AH,14,0) -> 1.5386 | J141: =VLOOKUP(H141,[1]Meta文库质检结果汇总表!$E$3104:$Q$3355,13,0) -> 519
A142: KC190221-007 MAKF181229011-浙大93个样本的16S区域扩增子建库测序技术服务（委托）合同-2期26例-16sV4-V5-测序分析任务单 | B142: B61 40 | C142: HF190111026 | D142: 16sV4-V5 | E142: 0.06 | F142: 56-81 | G142: Meta 61，A02 | H142: HFMET190125A0199-56-81 | I142: =VLOOKUP(H142,[1]Meta文库质检结果汇总表!$E:$AH,14,0) -> 5.6764 | J142: =VLOOKUP(H142,[1]Meta文库质检结果汇总表!$E$3104:$Q$3355,13,0) -> 538
A143: KC190221-007 MAKF181229011-浙大93个样本的16S区域扩增子建库测序技术服务（委托）合同-2期26例-16sV4-V5-测序分析任务单 | B143: B61 43 | C143: HF190111027 | D143: 16sV4-V5 | E143: 0.06 | F143: 57-81 | G143: Meta 62，G03 | H143: HFMET190129B0200-57-81 | I143: =VLOOKUP(H143,[1]Meta文库质检结果汇总表!$E:$AH,14,0) -> 0.7585 | J143: =VLOOKUP(H143,[1]Meta文库质检结果汇总表!$E$3104:$Q$3355,13,0) -> 527
A144: KC190221-007 MAKF181229011-浙大93个样本的16S区域扩增子建库测序技术服务（委托）合同-2期26例-16sV4-V5-测序分析任务单 | B144: B61 44 | C144: HF190111028 | D144: 16sV4-V5 | E144: 0.06 | F144: 58-81 | G144: Meta 62，G04 | H144: HFMET190129B0201-58-81 | I144: =VLOOKUP(H144,[1]Meta文库质检结果汇总表!$E:$AH,14,0) -> 5.7638 | J144: =VLOOKUP(H144,[1]Meta文库质检结果汇总表!$E$3104:$Q$3355,13,0) -> 525
A145: KC190221-007 MAKF181229011-浙大93个样本的16S区域扩增子建库测序技术服务（委托）合同-2期26例-16sV4-V5-测序分析任务单 | B145: B61 80 | C145: HF190111029 | D145: 16sV4-V5 | E145: 0.06 | F145: 51-82 | G145: Meta 61，A05 | H145: HFMET190125A0202-51-82 | I145: =VLOOKUP(H145,[1]Meta文库质检结果汇总表!$E:$AH,14,0) -> 4.3817 | J145: =VLOOKUP(H145,[1]Meta文库质检结果汇总表!$E$3104:$Q$3355,13,0) -> 518
A146: KC190221-007 MAKF181229011-浙大93个样本的16S区域扩增子建库测序技术服务（委托）合同-2期26例-16sV4-V5-测序分析任务单 | B146: B61 77 | C146: HF190111031 | D146: 16sV4-V5 | E146: 0.06 | F146: 53-82 | G146: Meta 61，A07 | H146: HFMET190125A0204-53-82 | I146: =VLOOKUP(H146,[1]Meta文库质检结果汇总表!$E:$AH,14,0) -> 0.6601 | J146: =VLOOKUP(H146,[1]Meta文库质检结果汇总表!$E$3104:$Q$3355,13,0) -> 517
A147: KC190221-007 MAKF181229011-浙大93个样本的16S区域扩增子建库测序技术服务（委托）合同-2期26例-16sV4-V5-测序分析任务单 | B147: B61 75 | C147: HF190111033 | D147: 16sV4-V5 | E147: 0.06 | F147: 55-82 | G147: Meta 61，A09 | H147: HFMET190125A0206-55-82 | I147: =VLOOKUP(H147,[1]Meta文库质检结果汇总表!$E:$AH,14,0) -> 9.5237 | J147: =VLOOKUP(H147,[1]Meta文库质检结果汇总表!$E$3104:$Q$3355,13,0) -> 524
A148: KC190221-007 MAKF181229011-浙大93个样本的16S区域扩增子建库测序技术服务（委托）合同-2期26例-16sV4-V5-测序分析任务单 | B148: B61 71 | C148: HF190111034 | D148: 16sV4-V5 | E148: 0.06 | F148: 56-82 | G148: Meta 61，A10 | H148: HFMET190125A0207-56-82 | I148: =VLOOKUP(H148,[1]Meta文库质检结果汇总表!$E:$AH,14,0) -> 8.2196 | J148: =VLOOKUP(H148,[1]Meta文库质检结果汇总表!$E$3104:$Q$3355,13,0) -> 531
A149: KC190221-007 MAKF181229011-浙大93个样本的16S区域扩增子建库测序技术服务（委托）合同-2期26例-16sV4-V5-测序分析任务单 | B149: B61 53 | C149: HF190111035 | D149: 16sV4-V5 | E149: 0.06 | F149: 57-82 | G149: Meta 61，A11 | H149: HFMET190125A0208-57-82 | I149: =VLOOKUP(H149,[1]Meta文库质检结果汇总表!$E:$AH,14,0) -> 2.142 | J149: =VLOOKUP(H149,[1]Meta文库质检结果汇总表!$E$3104:$Q$3355,13,0) -> 538
...
